import { fetchApi, fetchWithAuth, } from "@/hooks/api";
import { createToken } from "@/hooks/token";
import { CreateUser, EditUser, ListUser, LoginUser } from "./types";
import { createUser } from "@/hooks/user";

export const registerUser = async (data: CreateUser): Promise<CreateUser> => {
    try {
        const res = await fetchWithAuth<CreateUser>("/user", { method: "POST", data: data });
        return res;
    } catch (error: any) {
        throw new Error(error.message);
    }
};

export const loginUser = async (email: string, password: string, session: boolean) => {
    try {
        const res: any = await fetchApi("/auth/login", { method: "POST", data: { email, password } });
        await createToken(res.session.session.access_token, session);
        await createUser(res.profile, session);
        return res;
    } catch (error) {
        throw new Error(error instanceof Error ? error.message : 'An unknown error occurred');
    }
};

export const profileUser = async (): Promise<ListUser> => {
    try {
        const res = await fetchWithAuth<ListUser>("/auth/profile", { method: "GET" });
        return res;
    } catch (error) {
        throw new Error(error instanceof Error ? error.message : 'An unknown error occurred');
    }
};

export const showUser = async (id: string): Promise<ListUser> => {
    try {
        const res = await fetchWithAuth<ListUser>("/users/" + id, { method: "GET" });
        return res;
    } catch (error) {
        throw new Error(error instanceof Error ? error.message : 'An unknown error occurred');
    }
};

export const editUser = async (data: EditUser): Promise<EditUser> => {
    try {
        const res = await fetchWithAuth<EditUser>("/auth/edit/", {
            method: "PUT", data: {
                name: data.name, 
                phone: data.phone
            }
        });
        return res;
    } catch (error) {
        throw new Error(error instanceof Error ? error.message : 'An unknown error occurred');
    }
};

export const excludeUser = async () => {
    try {
        const res: any = await fetchWithAuth("/user", { method: "DELETE" });
        return res;
    } catch (error) {
        console.log(error)
        throw new Error(error instanceof Error ? error.message : 'An unknown error occurred');
    }
};

